<?xml version="1.0" encoding="utf-8"?>
<!-- This URDF was automatically created by SolidWorks to URDF Exporter! Originally created by Stephen Brawner (brawner@gmail.com) 
     Commit Version: 1.6.0-4-g7f85cfe  Build Version: 1.6.7995.38578
     For more information, please see http://wiki.ros.org/sw_urdf_exporter -->
<robot
  name="RXL-6F-C3">
  <link
    name="base_link">
    <inertial>
      <origin
        xyz="3.53515085054106E-05 -0.000344112995119752 0.0504743485122056"
        rpy="0 0 0" />
      <mass
        value="0.651913537431336" />
      <inertia
        ixx="0.000695985861740904"
        ixy="2.0688102027219E-06"
        ixz="2.11905962706114E-06"
        iyy="0.00068109446381714"
        iyz="-6.83989723679503E-06"
        izz="0.000727115124181003" />
    </inertial>
    <visual>
      <origin
        xyz="0 0 0"
        rpy="0 0 0" />
      <geometry>
        <mesh
          filename="package://RXL-6F-C3/meshes/base_link.STL" />
      </geometry>
      <material
        name="">
        <color
          rgba="0.792156862745098 0.819607843137255 0.933333333333333 1" />
      </material>
    </visual>
    <collision>
      <origin
        xyz="0 0 0"
        rpy="0 0 0" />
      <geometry>
        <mesh
          filename="package://RXL-6F-C3/meshes/base_link.STL" />
      </geometry>
    </collision>
  </link>
  <link
    name="Link1">
    <inertial>
      <origin
        xyz="0.488E-3 -13.727E-3 -10.765E-3"
        rpy="0 0 0" />
      <mass
        value="1.559" />
      <inertia
        ixx="2661.9E-6"
        ixy="-31.029E-6"
        ixz="9.34E-6"
        iyy="2302.5E-6"
        iyz="151.466E-6"
        izz="1676359E-6" />
    </inertial>
    <visual>
      <origin
        xyz="0 0 0"
        rpy="0 0 0" />
      <geometry>
        <mesh
          filename="package://RXL-6F-C3/meshes/Link1.STL" />
      </geometry>
      <material
        name="">
        <color
          rgba="0.925490196078431 0.925490196078431 0.905882352941176 1" />
      </material>
    </visual>
    <collision>
      <origin
        xyz="0 0 0"
        rpy="0 0 0" />
      <geometry>
        <mesh
          filename="package://RXL-6F-C3/meshes/Link1.STL" />
      </geometry>
    </collision>
  </link>
  <joint
    name="J1"
    type="revolute">
    <origin
      xyz="0 0 0.191500058118611"
      rpy="0 0 0" />
    <parent
      link="base_link" />
    <child
      link="Link1" />
    <axis
      xyz="0 0 1" />
    <limit
      lower="-3.0194"
      upper="3.0194"
      effort="60"
      velocity="3.14" />
  </joint>
  <link
    name="Link2L">
    <inertial>
      <origin
        xyz="-0.112E-3 -148.134E-3 4.111E-3"
        rpy="0 0 0" />
      <mass
        value="1.394" />
      <inertia
        ixx="6927.3E-6"
        ixy="0"
        ixz="-2.6E-6"
        iyy="1045E-6"
        iyz="-801E-6"
        izz="6864E-6" />
    </inertial>
    <visual>
      <origin
        xyz="0 0 0"
        rpy="0 0 0" />
      <geometry>
        <mesh
          filename="package://RXL-6F-C3/meshes/Link2L.STL" />
      </geometry>
      <material
        name="">
        <color
          rgba="0.925490196078431 0.925490196078431 0.905882352941176 1" />
      </material>
    </visual>
    <collision>
      <origin
        xyz="0 0 0"
        rpy="0 0 0" />
      <geometry>
        <mesh
          filename="package://RXL-6F-C3/meshes/Link2L.STL" />
      </geometry>
    </collision>
  </link>
  <joint
    name="J2L"
    type="revolute">
    <origin
      xyz="0 0 0"
      rpy="-1.57079632679489 -1.5707963267949 0" />
    <parent
      link="Link1" />
    <child
      link="Link2L" />
    <axis
      xyz="0 0 1" />
    <limit
      lower="-0.6109"
      upper="3.1067"
      effort="60"
      velocity="3.14" />
  </joint>
  <link
    name="Link3">
    <inertial>
      <origin
        xyz="0.032E-3 15.649E-3 -11.225E-3"
        rpy="0 0 0" />
      <mass
        value="1.117" />
      <inertia
        ixx="1757E-6"
        ixy="0"
        ixz="0"
        iyy="1468E-6"
        iyz="-112E-6"
        izz="979E-6" />
    </inertial>
    <visual>
      <origin
        xyz="0 0 0"
        rpy="0 0 0" />
      <geometry>
        <mesh
          filename="package://RXL-6F-C3/meshes/Link3.STL" />
      </geometry>
      <material
        name="">
        <color
          rgba="0.925490196078431 0.925490196078431 0.905882352941176 1" />
      </material>
    </visual>
    <collision>
      <origin
        xyz="0 0 0"
        rpy="0 0 0" />
      <geometry>
        <mesh
          filename="package://RXL-6F-C3/meshes/Link3.STL" />
      </geometry>
    </collision>
  </link>
  <joint
    name="J3"
    type="revolute">
    <origin
      xyz="0 -0.322 0"
      rpy="1.5707963267949 -1.5707963267949 0" />
    <parent
      link="Link2L" />
    <child
      link="Link3" />
    <axis
      xyz="0 0 1" />
    <limit
      lower="-3.0194"
      upper="3.0194"
      effort="30"
      velocity="3.925" />
  </joint>
  <link
    name="Link4">
    <inertial>
      <origin
        xyz="-0.001E-3 85.449E-3 4.844E-3"
        rpy="0 0 0" />
      <mass
        value="0.673" />
      <inertia
        ixx="1283E-6"
        ixy="0"
        ixz="0"
        iyy="344E-6"
        iyz="229E-6"
        izz="1257E-6" />
    </inertial>
    <visual>
      <origin
        xyz="0 0 0"
        rpy="0 0 0" />
      <geometry>
        <mesh
          filename="package://RXL-6F-C3/meshes/Link4.STL" />
      </geometry>
      <material
        name="">
        <color
          rgba="1 1 1 1" />
      </material>
    </visual>
    <collision>
      <origin
        xyz="0 0 0"
        rpy="0 0 0" />
      <geometry>
        <mesh
          filename="package://RXL-6F-C3/meshes/Link4.STL" />
      </geometry>
    </collision>
  </link>
  <joint
    name="J4"
    type="revolute">
    <origin
      xyz="0 0 0"
      rpy="1.5707963267949 0 0" />
    <parent
      link="Link3" />
    <child
      link="Link4" />
    <axis
      xyz="0 0 1" />
    <limit
      lower="-2.2689"
      upper="0.2618"
      effort="30"
      velocity="3.925" />
  </joint>
  <link
    name="Link5">
    <inertial>
      <origin
        xyz="-0.001E-3 -14.741E-3 -80.627E-3"
        rpy="0 0 0" />
      <mass
        value="1.13" />
      <inertia
        ixx="2343E-6"
        ixy="0"
        ixz="0"
        iyy="1934E-6"
        iyz="443E-6"
        izz="1091E-6" />
    </inertial>
    <visual>
      <origin
        xyz="0 0 0"
        rpy="0 0 0" />
      <geometry>
        <mesh
          filename="package://RXL-6F-C3/meshes/Link5.STL" />
      </geometry>
      <material
        name="">
        <color
          rgba="0.529411764705882 0.549019607843137 0.549019607843137 1" />
      </material>
    </visual>
    <collision>
      <origin
        xyz="0 0 0"
        rpy="0 0 0" />
      <geometry>
        <mesh
          filename="package://RXL-6F-C3/meshes/Link5.STL" />
      </geometry>
    </collision>
  </link>
  <joint
    name="J5"
    type="revolute">
    <origin
      xyz="0 0.2755 0"
      rpy="-1.5707963267949 0 0" />
    <parent
      link="Link4" />
    <child
      link="Link5" />
    <axis
      xyz="0 0 1" />
    <limit
      lower="-3.0194"
      upper="3.0194"
      effort="10"
      velocity="3.925" />
  </joint>
  <link
    name="Link6">
    <inertial>
      <origin
        xyz="13.909E-3 -1.02E-3 3.245E-3"
        rpy="0 0 0" />
      <mass
        value="0.559" />
      <inertia
        ixx="354E-6"
        ixy="0"
        ixz="27E-6"
        iyy="288E-6"
        iyz="0"
        izz="312E-6" />
    </inertial>
    <visual>
      <origin
        xyz="0 0 0"
        rpy="0 0 0" />
      <geometry>
        <mesh
          filename="package://RXL-6F-C3/meshes/Link6.STL" />
      </geometry>
      <material
        name="">
        <color
          rgba="0.79216 0.81961 0.93333 1" />
      </material>
    </visual>
    <collision>
      <origin
        xyz="0 0 0"
        rpy="0 0 0" />
      <geometry>
        <mesh
          filename="package://RXL-6F-C3/meshes/Link6.STL" />
      </geometry>
    </collision>
  </link>
  <joint
    name="J6"
    type="revolute">
    <origin
      xyz="0 0 0"
      rpy="1.5708 -1.5708 0" />
    <parent
      link="Link5" />
    <child
      link="Link6" />
    <axis
      xyz="0 0 1" />
    <limit
      lower="-0.9599"
      upper="0.9599"
      effort="10"
      velocity="3.925" />
  </joint>
  <link
    name="Link7">
    <inertial>
      <origin
        xyz="20E-3 -71E-3 4.396E-3"
        rpy="0 0 0" />
      <mass
        value="0.483" />
      <inertia
        ixx="810E-6"
        ixy="154E-6"
        ixz="41E-6"
        iyy="1152E-6"
        iyz="-133E-6"
        izz="1640E-6" />
    </inertial>
    <visual>
      <origin
        xyz="0 0 0"
        rpy="0 0 0" />
      <geometry>
        <mesh
          filename="package://RXL-6F-C3/meshes/Link7.STL" />
      </geometry>
      <material
        name="">
        <color
          rgba="0.898039215686275 0.917647058823529 0.929411764705882 1" />
      </material>
    </visual>
    <collision>
      <origin
        xyz="0 0 0"
        rpy="0 0 0" />
      <geometry>
        <mesh
          filename="package://RXL-6F-C3/meshes/Link7.STL" />
      </geometry>
    </collision>
  </link>
  <joint
    name="J7"
    type="revolute">
    <origin
      xyz="0.0155 0 0"
      rpy="1.5708 -1.5708 0" />
    <parent
      link="Link6" />
    <child
      link="Link7" />
    <axis
      xyz="0 0 1" />
    <limit
      lower="-1.9024"
      upper="0.6109"
      effort="10"
      velocity="3.925" />
  </joint>
  <link
    name="Link8">
    <inertial>
      <origin
        xyz="-0.000 0 0"
        rpy="0 0 0" />
      <mass
        value="0.0" />
      <inertia
        ixx="0"
        ixy="0"
        ixz="0"
        iyy="0"
        iyz="0"
        izz="0" />
    </inertial>
    <visual>
      <origin
        xyz="0 0 0"
        rpy="0 0 0" />
      <geometry>
        <mesh
          filename="package://RXL-6F-C3/meshes/Link8.STL" />
      </geometry>
      <material
        name="">
        <color
          rgba="0.89804 0.91765 0.92941 1" />
      </material>
    </visual>
    <collision>
      <origin
        xyz="0 0 0"
        rpy="0 0 0" />
      <geometry>
        <mesh
          filename="package://RXL-6F-C3/meshes/Link8.STL" />
      </geometry>
    </collision>
  </link>
  <joint
    name="J8"
    type="fixed">
    <origin
      xyz="0 -0.0962000041171294 0"
      rpy="1.57079632679489 0 0" />
    <parent
      link="Link7" />
    <child
      link="Link8" />
    <axis
      xyz="0 0 1" />
    <limit
      lower="0"
      upper="0"
      effort="0"
      velocity="0" />
  </joint>
</robot>