<?xml version="1.0" encoding="utf-8"?>
<!-- This URDF was automatically created by SolidWorks to URDF Exporter! Originally created by Stephen Brawner (brawner@gmail.com) 
     Commit Version: 1.6.0-1-g15f4949  Build Version: 1.6.7594.29634
     For more information, please see http://wiki.ros.org/sw_urdf_exporter -->
<robot
  name="eco656weili.sldasm">
  <link
    name="baselink">
    <inertial>
      <origin
        xyz="0.000599817353042905 -9.29318232073179E-05 0.0433014167978046"
        rpy="0 0 0" />
      <mass
        value="0.611273147318723" />
      <inertia
        ixx="0.000802124722490711"
        ixy="3.02805759603546E-06"
        ixz="-2.87471743737186E-05"
        iyy="0.000805018605821677"
        iyz="1.97489777184639E-06"
        izz="0.00066167330387865" />
    </inertial>
    <visual>
      <origin
        xyz="0 0 0"
        rpy="0 0 0" />
      <geometry>
        <mesh
          filename="package://eco656weili.sldasm/meshes/baselink.STL" />
      </geometry>
      <material
        name="">
        <color
          rgba="1 1 0.945098039215686 1" />
      </material>
    </visual>
    <collision>
      <origin
        xyz="0 0 0"
        rpy="0 0 0" />
      <geometry>
        <mesh
          filename="package://eco656weili.sldasm/meshes/baselink.STL" />
      </geometry>
    </collision>
  </link>
  <link
    name="Link1">
    <inertial>
      <origin
        xyz="-0.022858 -2.0784E-06 -0.013658"
        rpy="0 0 0" />
      <mass
        value="1.5078" />
      <inertia
        ixx="0.00081398"
        ixy="-1.9024E-05"
        ixz="0.00022746"
        iyy="0.001848"
        iyz="2.0444E-06"
        izz="0.0015286" />
    </inertial>
    <visual>
      <origin
        xyz="0 0 0"
        rpy="0 0 0" />
      <geometry>
        <mesh
          filename="package://eco656weili.sldasm/meshes/Link1.STL" />
      </geometry>
      <material
        name="">
        <color
          rgba="1 1 0.9451 1" />
      </material>
    </visual>
    <collision>
      <origin
        xyz="0 0 0"
        rpy="0 0 0" />
      <geometry>
        <mesh
          filename="package://eco656weili.sldasm/meshes/Link1.STL" />
      </geometry>
    </collision>
  </link>
  <joint
    name="joint1"
    type="revolute">
    <origin
      xyz="0 0 0.1625"
      rpy="0 0 0" />
    <parent
      link="baselink" />
    <child
      link="Link1" />
    <axis
      xyz="0 0 -1" />
    <limit
      lower="-3.14"
      upper="3.14"
      effort="100"
      velocity="1" />
  </joint>
  <link
    name="Link2">
    <inertial>
      <origin
        xyz="-1.6049E-06 0.10336 0.067332"
        rpy="0 0 0" />
      <mass
        value="2.0227" />
      <inertia
        ixx="0.012821"
        ixy="-7.2979E-08"
        ixz="1.1499E-08"
        iyy="0.0011237"
        iyz="-0.00033755"
        izz="0.012933" />
    </inertial>
    <visual>
      <origin
        xyz="0 0 0"
        rpy="0 0 0" />
      <geometry>
        <mesh
          filename="package://eco656weili.sldasm/meshes/Link2.STL" />
      </geometry>
      <material
        name="">
        <color
          rgba="1 1 0.9451 1" />
      </material>
    </visual>
    <collision>
      <origin
        xyz="0 0 0"
        rpy="0 0 0" />
      <geometry>
        <mesh
          filename="package://eco656weili.sldasm/meshes/Link2.STL" />
      </geometry>
    </collision>
  </link>
  <joint
    name="joint2"
    type="revolute">
    <origin
      xyz="-0.086 0 0"
      rpy="1.5708 0 0" />
    <parent
      link="Link1" />
    <child
      link="Link2" />
    <axis
      xyz="3.5522E-05 0 -1" />
    <limit
      lower="-3.14"
      upper="1.92"
      effort="100"
      velocity="1" />
  </joint>
  <link
    name="Link3">
    <inertial>
      <origin
        xyz="9.8625E-08 -0.10374 0.018603"
        rpy="0 0 0" />
      <mass
        value="1.8858" />
      <inertia
        ixx="0.0094046"
        ixy="1.4618E-10"
        ixz="1.7723E-09"
        iyy="0.0008412"
        iyz="0.00068646"
        izz="0.0092481" />
    </inertial>
    <visual>
      <origin
        xyz="0 0 0"
        rpy="0 0 0" />
      <geometry>
        <mesh
          filename="package://eco656weili.sldasm/meshes/Link3.STL" />
      </geometry>
      <material
        name="">
        <color
          rgba="1 1 0.9451 1" />
      </material>
    </visual>
    <collision>
      <origin
        xyz="0 0 0"
        rpy="0 0 0" />
      <geometry>
        <mesh
          filename="package://eco656weili.sldasm/meshes/Link3.STL" />
      </geometry>
    </collision>
  </link>
  <joint
    name="joint3"
    type="revolute">
    <origin
      xyz="0 0.260000000001112 0"
      rpy="3.14159265358979 0 1.5707963267949" />
    <parent
      link="Link2" />
    <child
      link="Link3" />
    <axis
      xyz="0 -3.55216483642536E-05 -0.999999999364838" />
    <limit
      lower="-2.79"
      upper="2.53"
      effort="100"
      velocity="1" />
  </joint>
  <link
    name="Link4">
    <inertial>
      <origin
        xyz="-0.0069819 -0.016329 0.0067507"
        rpy="0 0 0" />
      <mass
        value="0.5701" />
      <inertia
        ixx="0"
        ixy="0"
        ixz="0"
        iyy="0"
        iyz="0"
        izz="0" />
    </inertial>
    <visual>
      <origin
        xyz="0 0 0"
        rpy="0 0 0" />
      <geometry>
        <mesh
          filename="package://eco656weili.sldasm/meshes/Link4.STL" />
      </geometry>
      <material
        name="">
        <color
          rgba="1 1 0.9451 1" />
      </material>
    </visual>
    <collision>
      <origin
        xyz="0 0 0"
        rpy="0 0 0" />
      <geometry>
        <mesh
          filename="package://eco656weili.sldasm/meshes/Link4.STL" />
      </geometry>
    </collision>
  </link>
  <joint
    name="joint4"
    type="revolute">
    <origin
      xyz="0 -0.24 -0.05888"
      rpy="0 0 1.5708" />
    <parent
      link="Link3" />
    <child
      link="Link4" />
    <axis
      xyz="-3.5522E-05 0 -1" />
    <limit
      lower="-2.44"
      upper="2.44"
      effort="100"
      velocity="1" />
  </joint>
  <link
    name="Link5">
    <inertial>
      <origin
        xyz="6.1046E-07 0.006642 -0.012647"
        rpy="0 0 0" />
      <mass
        value="0.6414" />
      <inertia
        ixx="0.00024751"
        ixy="-5.6849E-09"
        ixz="5.4838E-10"
        iyy="0.00017648"
        iyz="-2.8552E-05"
        izz="0.00019295" />
    </inertial>
    <visual>
      <origin
        xyz="0 0 0"
        rpy="0 0 0" />
      <geometry>
        <mesh
          filename="package://eco656weili.sldasm/meshes/Link5.STL" />
      </geometry>
      <material
        name="">
        <color
          rgba="0.29804 0.28627 0.28235 1" />
      </material>
    </visual>
    <collision>
      <origin
        xyz="0 0 0"
        rpy="0 0 0" />
      <geometry>
        <mesh
          filename="package://eco656weili.sldasm/meshes/Link5.STL" />
      </geometry>
    </collision>
  </link>
  <joint
    name="joint5"
    type="revolute">
    <origin
      xyz="0 -0.11 0"
      rpy="1.5708 0 0" />
    <parent
      link="Link4" />
    <child
      link="Link5" />
    <axis
      xyz="0 0 -1" />
    <limit
      lower="-3.14"
      upper="3.14"
      effort="100"
      velocity="1" />
  </joint>
  <link
    name="Link6">
    <inertial>
      <origin
        xyz="0.00034235 -0.00018942 -0.028577"
        rpy="0 0 0" />
      <mass
        value="0.19" />
      <inertia
        ixx="7.0593E-05"
        ixy="-1.192E-06"
        ixz="-8.0833E-07"
        iyy="6.9259E-05"
        iyz="4.3436E-07"
        izz="6.1808E-05" />
    </inertial>
    <visual>
      <origin
        xyz="0 0 0"
        rpy="0 0 0" />
      <geometry>
        <mesh
          filename="package://eco656weili.sldasm/meshes/Link6.STL" />
      </geometry>
      <material
        name="">
        <color
          rgba="0.75294 0.75294 0.75294 1" />
      </material>
    </visual>
    <collision>
      <origin
        xyz="0 0 0"
        rpy="0 0 0" />
      <geometry>
        <mesh
          filename="package://eco656weili.sldasm/meshes/Link6.STL" />
      </geometry>
    </collision>
  </link>
  <joint
    name="joint6"
    type="revolute">
    <origin
      xyz="0 0.108 0"
      rpy="-1.5708 0 0" />
    <parent
      link="Link5" />
    <child
      link="Link6" />
    <axis
      xyz="-3.5522E-05 0 -1" />
    <limit
      lower="-3.14"
      upper="3.14"
      effort="100"
      velocity="1" />
  </joint>
</robot>