<?xml version="1.0" encoding="utf-8"?>
<!-- This URDF was automatically created by SolidWorks to URDF Exporter! Originally created by Stephen Brawner (brawner@gmail.com) 
     Commit Version: 1.6.0-1-g15f4949  Build Version: 1.6.7594.29634
     For more information, please see http://wiki.ros.org/sw_urdf_exporter -->
<robot
  name="RML-63-6FA">
  <link
    name="base_link">
    <inertial>
      <origin
        xyz="0.00020508 -8.2579E-05 0.043092"
        rpy="0 0 0" />
      <mass
        value="1.6314" />
      <inertia
        ixx="0.0022252"
        ixy="7.9009E-06"
        ixz="-7.7557E-05"
        iyy="0.0022156"
        iyz="5.984E-06"
        izz="0.0018513" />
    </inertial>
    <visual>
      <origin
        xyz="0 0 0"
        rpy="0 0 0" />
      <geometry>
        <mesh
          filename="package://RML-63-6FA/meshes/base_link.STL" />
      </geometry>
      <material
        name="">
        <color
          rgba="0.86667 0.86667 0.8902 1" />
      </material>
    </visual>
    <collision>
      <origin
        xyz="0 0 0"
        rpy="0 0 0" />
      <geometry>
        <mesh
          filename="package://RML-63-6FA/meshes/base_link.STL" />
      </geometry>
    </collision>
  </link>
  <link
    name="Link_1">
    <inertial>
      <origin
        xyz="-0.030909 -0.0013023 -0.0053124"
        rpy="0 0 0" />
      <mass
        value="1.7668" />
      <inertia
        ixx="0.0014534"
        ixy="-0.00017578"
        ixz="0.00028019"
        iyy="0.0043772"
        iyz="1.7209E-05"
        izz="0.0040911" />
    </inertial>
    <visual>
      <origin
        xyz="0 0 0"
        rpy="0 0 0" />
      <geometry>
        <mesh
          filename="package://RML-63-6FA/meshes/Link_1.STL" />
      </geometry>
      <material
        name="">
        <color
          rgba="1 1 1 1" />
      </material>
    </visual>
    <collision>
      <origin
        xyz="0 0 0"
        rpy="0 0 0" />
      <geometry>
        <mesh
          filename="package://RML-63-6FA/meshes/Link_1.STL" />
      </geometry>
    </collision>
  </link>
  <joint
    name="joint_1"
    type="revolute">
    <origin
      xyz="0 0 0.1625"
      rpy="0 0 0" />
    <parent
      link="base_link" />
    <child
      link="Link_1" />
    <axis
      xyz="0 0 1" />
    <limit
      lower="-3.107"
      upper="3.107"
      effort="60"
      velocity="3.14" />
  </joint>
  <link
    name="Link_2">
    <inertial>
      <origin
        xyz="0.16852 9.5319E-07 -0.077257"
        rpy="0 0 0" />
      <mass
        value="4.3415" />
      <inertia
        ixx="0.0028306"
        ixy="3.2507E-07"
        ixz="4.0422E-06"
        iyy="0.075435"
        iyz="-3.2304E-08"
        izz="0.075923" />
    </inertial>
    <visual>
      <origin
        xyz="0 0 0"
        rpy="0 0 0" />
      <geometry>
        <mesh
          filename="package://RML-63-6FA/meshes/Link_2.STL" />
      </geometry>
      <material
        name="">
        <color
          rgba="0.86667 0.86667 0.8902 1" />
      </material>
    </visual>
    <collision>
      <origin
        xyz="0 0 0"
        rpy="0 0 0" />
      <geometry>
        <mesh
          filename="package://RML-63-6FA/meshes/Link_2.STL" />
      </geometry>
    </collision>
  </link>
  <joint
    name="joint_2"
    type="revolute">
    <origin
      xyz="-0.086 0 0"
      rpy="-1.5708 -1.5708 0" />
    <parent
      link="Link_1" />
    <child
      link="Link_2" />
    <axis
      xyz="0 0 1" />
    <limit
      lower="-3.107"
      upper="3.107"
      effort="60"
      velocity="3.14" />
  </joint>
  <link
    name="Link_3">
    <inertial>
      <origin
        xyz="0.034488 -0.010948 -0.0056237"
        rpy="0 0 0" />
      <mass
        value="1.7286" />
      <inertia
        ixx="0.0014154"
        ixy="0.00068025"
        ixz="-0.00043307"
        iyy="0.0026049"
        iyz="0.00017201"
        izz="0.0028551" />
    </inertial>
    <visual>
      <origin
        xyz="0 0 0"
        rpy="0 0 0" />
      <geometry>
        <mesh
          filename="package://RML-63-6FA/meshes/Link_3.STL" />
      </geometry>
      <material
        name="">
        <color
          rgba="0.86667 0.86667 0.8902 1" />
      </material>
    </visual>
    <collision>
      <origin
        xyz="0 0 0"
        rpy="0 0 0" />
      <geometry>
        <mesh
          filename="package://RML-63-6FA/meshes/Link_3.STL" />
      </geometry>
    </collision>
  </link>
  <joint
    name="joint_3"
    type="revolute">
    <origin
      xyz="0.38 0 0"
      rpy="0 0 1.5708" />
    <parent
      link="Link_2" />
    <child
      link="Link_3" />
    <axis
      xyz="0 0 1" />
    <limit
      lower="-3.107"
      upper="2.531"
      effort="30"
      velocity="3.14" />
  </joint>
  <link
    name="Link_4">
    <inertial>
      <origin
        xyz="-3.7483E-07 -0.03048 -0.1974"
        rpy="0 0 0" />
      <mass
        value="2.4735" />
      <inertia
        ixx="0.026022"
        ixy="-4.0463E-08"
        ixz="1.6128E-07"
        iyy="0.024376"
        iyz="0.0061667"
        izz="0.0029583" />
    </inertial>
    <visual>
      <origin
        xyz="0 0 0"
        rpy="0 0 0" />
      <geometry>
        <mesh
          filename="package://RML-63-6FA/meshes/Link_4.STL" />
      </geometry>
      <material
        name="">
        <color
          rgba="0.86667 0.86667 0.8902 1" />
      </material>
    </visual>
    <collision>
      <origin
        xyz="0 0 0"
        rpy="0 0 0" />
      <geometry>
        <mesh
          filename="package://RML-63-6FA/meshes/Link_4.STL" />
      </geometry>
    </collision>
  </link>
  <joint
    name="joint_4"
    type="revolute">
    <origin
      xyz="0.069 -0.405 0"
      rpy="1.5708 0 0" />
    <parent
      link="Link_3" />
    <child
      link="Link_4" />
    <axis
      xyz="0 0 1" />
    <limit
      lower="-3.107"
      upper="3.107"
      effort="30"
      velocity="3.14" />
  </joint>
  <link
    name="Link_5">
    <inertial>
      <origin
        xyz="5.0765E-06 0.025125 -0.0072564"
        rpy="0 0 0" />
      <mass
        value="0.93167" />
      <inertia
        ixx="0.0012563"
        ixy="-1.8306E-08"
        ixz="4.4539E-09"
        iyy="0.00053793"
        iyz="-0.00017338"
        izz="0.0011134" />
    </inertial>
    <visual>
      <origin
        xyz="0 0 0"
        rpy="0 0 0" />
      <geometry>
        <mesh
          filename="package://RML-63-6FA/meshes/Link_5.STL" />
      </geometry>
      <material
        name="">
        <color
          rgba="0.86667 0.86667 0.8902 1" />
      </material>
    </visual>
    <collision>
      <origin
        xyz="0 0 0"
        rpy="0 0 0" />
      <geometry>
        <mesh
          filename="package://RML-63-6FA/meshes/Link_5.STL" />
      </geometry>
    </collision>
  </link>
  <joint
    name="joint_5"
    type="revolute">
    <origin
      xyz="0 0 0"
      rpy="1.5708 0 3.1416" />
    <parent
      link="Link_4" />
    <child
      link="Link_5" />
    <axis
      xyz="0 0 1" />
    <limit
      lower="-3.107"
      upper="3.107"
      effort="10"
      velocity="3.9" />
  </joint>
  <link
    name="Link_6">
    <inertial>
      <origin
        xyz="6.4619E-06 -0.00036611 0.028985"
        rpy="0 0 0" />
      <mass
        value="0.14843" />
      <inertia
        ixx="7.016E-05"
        ixy="1.6085E-08"
        ixz="-2.5145E-08"
        iyy="7.3141E-05"
        iyz="9.0637E-07"
        izz="6.305E-05" />
    </inertial>
    <visual>
      <origin
        xyz="0 0 0"
        rpy="0 0 0" />
      <geometry>
        <mesh
          filename="package://RML-63-6FA/meshes/Link_6.STL" />
      </geometry>
      <material
        name="">
        <color
          rgba="1 1 1 1" />
      </material>
    </visual>
    <collision>
      <origin
        xyz="0 0 0"
        rpy="0 0 0" />
      <geometry>
        <mesh
          filename="package://RML-63-6FA/meshes/Link_6.STL" />
      </geometry>
    </collision>
  </link>
  <joint
    name="joint_6"
    type="continuous">
    <origin
      xyz="0 0.085999 0"
      rpy="-1.5708 1.0472 0" />
    <parent
      link="Link_5" />
    <child
      link="Link_6" />
    <axis
      xyz="0 0 1" />
    <limit
      lower="-3.14"
      upper="3.14"
      effort="10"
      velocity="3.9" />
  </joint>
</robot>