<?xml version="1.0" encoding="utf-8"?>
<!-- This URDF was automatically created by SolidWorks to URDF Exporter! Originally created by Stephen Brawner (brawner@gmail.com) 
     Commit Version: 1.6.0-1-g15f4949  Build Version: 1.6.7594.29634
     For more information, please see http://wiki.ros.org/sw_urdf_exporter -->
<robot
  name="RML-63">
  <link
    name="base_link">
    <inertial>
      <origin
        xyz="0.000205095458476215 -8.25897842700144E-05 0.0430919385554682"
        rpy="0 0 0" />
      <mass
        value="1.6314377241954" />
      <inertia
        ixx="0.00222522953193642"
        ixy="7.90054592450178E-06"
        ixz="-7.75584915815644E-05"
        iyy="0.00221557162937843"
        iyz="5.98460319667916E-06"
        izz="0.00185133322888546" />
    </inertial>
    <visual>
      <origin
        xyz="0 0 0"
        rpy="0 0 0" />
      <geometry>
        <mesh
          filename="package://RML-63/meshes/base_link.STL" />
      </geometry>
      <material
        name="">
        <color
          rgba="0.866666666666667 0.866666666666667 0.890196078431372 1" />
      </material>
    </visual>
    <collision>
      <origin
        xyz="0 0 0"
        rpy="0 0 0" />
      <geometry>
        <mesh
          filename="package://RML-63/meshes/base_link.STL" />
      </geometry>
    </collision>
  </link>
  <link
    name="Link_1">
    <inertial>
      <origin
        xyz="-0.0309093768130494 -0.00130232011541856 -0.00531212893591626"
        rpy="0 0 0" />
      <mass
        value="1.76684172446222" />
      <inertia
        ixx="0.00145339217933016"
        ixy="-0.000175780933840043"
        ixz="0.000280199572531371"
        iyy="0.00437717210602588"
        iyz="1.72091374250754E-05"
        izz="0.00409113214373347" />
    </inertial>
    <visual>
      <origin
        xyz="0 0 0"
        rpy="0 0 0" />
      <geometry>
        <mesh
          filename="package://RML-63/meshes/Link_1.STL" />
      </geometry>
      <material
        name="">
        <color
          rgba="1 1 1 1" />
      </material>
    </visual>
    <collision>
      <origin
        xyz="0 0 0"
        rpy="0 0 0" />
      <geometry>
        <mesh
          filename="package://RML-63/meshes/Link_1.STL" />
      </geometry>
    </collision>
  </link>
  <joint
    name="joint_1"
    type="revolute">
    <origin
      xyz="0 0 0.1625"
      rpy="0 0 0" />
    <parent
      link="base_link" />
    <child
      link="Link_1" />
    <axis
      xyz="0 0 -1" />
    <limit
      lower="3.107"
      upper="-3.107"
      effort="100"
      velocity="1" />
  </joint>
  <link
    name="Link_2">
    <inertial>
      <origin
        xyz="0.168505404469421 1.9422928403956E-06 -0.0772578356377346"
        rpy="0 0 0" />
      <mass
        value="4.34134499577628" />
      <inertia
        ixx="0.00287613003637137"
        ixy="3.31323906269831E-07"
        ixz="0.000641025036104606"
        iyy="0.0843667915074823"
        iyz="-3.46283566890002E-08"
        izz="0.0848083231760969" />
    </inertial>
    <visual>
      <origin
        xyz="0 0 0"
        rpy="0 0 0" />
      <geometry>
        <mesh
          filename="package://RML-63/meshes/Link_2.STL" />
      </geometry>
      <material
        name="">
        <color
          rgba="0.866666666666667 0.866666666666667 0.890196078431372 1" />
      </material>
    </visual>
    <collision>
      <origin
        xyz="0 0 0"
        rpy="0 0 0" />
      <geometry>
        <mesh
          filename="package://RML-63/meshes/Link_2.STL" />
      </geometry>
    </collision>
  </link>
  <joint
    name="joint_2"
    type="revolute">
    <origin
      xyz="-0.086 0 0"
      rpy="-1.5708 -1.5708 0" />
    <parent
      link="Link_1" />
    <child
      link="Link_2" />
    <axis
      xyz="0 0 1" />
    <limit
      lower="3.107"
      upper="-3.107"
      effort="100"
      velocity="1" />
  </joint>
  <link
    name="Link_3">
    <inertial>
      <origin
        xyz="0.0344864637333194 -0.0109484427005764 -0.00562387040402216"
        rpy="0 0 0" />
      <mass
        value="1.72863066563727" />
      <inertia
        ixx="0.00158981569773471"
        ixy="0.000621020624737052"
        ixz="-0.000351344804114513"
        iyy="0.00311515423976902"
        iyz="0.000108576077680383"
        izz="0.0033780424164319" />
    </inertial>
    <visual>
      <origin
        xyz="0 0 0"
        rpy="0 0 0" />
      <geometry>
        <mesh
          filename="package://RML-63/meshes/Link_3.STL" />
      </geometry>
      <material
        name="">
        <color
          rgba="0.866666666666667 0.866666666666667 0.890196078431372 1" />
      </material>
    </visual>
    <collision>
      <origin
        xyz="0 0 0"
        rpy="0 0 0" />
      <geometry>
        <mesh
          filename="package://RML-63/meshes/Link_3.STL" />
      </geometry>
    </collision>
  </link>
  <joint
    name="joint_3"
    type="revolute">
    <origin
      xyz="0.38 0 0"
      rpy="0 0 1.5708" />
    <parent
      link="Link_2" />
    <child
      link="Link_3" />
    <axis
      xyz="0 0 1" />
    <limit
      lower="2.531"
      upper="-3.107"
      effort="100"
      velocity="1" />
  </joint>
  <link
    name="Link_4">
    <inertial>
      <origin
        xyz="3.61156287806419E-07 -0.0304813471484853 -0.197398146420985"
        rpy="0 0 0" />
      <mass
        value="2.47324011006769" />
      <inertia
        ixx="0.0315944518081002"
        ixy="-1.25336766795783E-07"
        ixz="3.28064107987395E-07"
        iyy="0.0296593257175899"
        iyz="0.00740390691546306"
        izz="0.00324790057612591" />
    </inertial>
    <visual>
      <origin
        xyz="0 0 0"
        rpy="0 0 0" />
      <geometry>
        <mesh
          filename="package://RML-63/meshes/Link_4.STL" />
      </geometry>
      <material
        name="">
        <color
          rgba="0.866666666666667 0.866666666666667 0.890196078431372 1" />
      </material>
    </visual>
    <collision>
      <origin
        xyz="0 0 0"
        rpy="0 0 0" />
      <geometry>
        <mesh
          filename="package://RML-63/meshes/Link_4.STL" />
      </geometry>
    </collision>
  </link>
  <joint
    name="joint_4"
    type="revolute">
    <origin
      xyz="0.06899998447855 -0.404999872232 0"
      rpy="1.5707963267949 0 0" />
    <parent
      link="Link_3" />
    <child
      link="Link_4" />
    <axis
      xyz="0 0 -1" />
    <limit
      lower="3.107"
      upper="-3.107"
      effort="100"
      velocity="1" />
  </joint>
  <link
    name="Link_5">
    <inertial>
      <origin
        xyz="5.2596479384534E-06 0.00725737101259333 0.0251248510443008"
        rpy="0 0 0" />
      <mass
        value="0.931616551800953" />
      <inertia
        ixx="0.00125629099911702"
        ixy="2.46688394581113E-09"
        ixz="-1.81152845846692E-08"
        iyy="0.00111339138667652"
        iyz="0.000173393424381638"
        izz="0.000537900826547747" />
    </inertial>
    <visual>
      <origin
        xyz="0 0 0"
        rpy="0 0 0" />
      <geometry>
        <mesh
          filename="package://RML-63/meshes/Link_5.STL" />
      </geometry>
      <material
        name="">
        <color
          rgba="0.866666666666667 0.866666666666667 0.890196078431372 1" />
      </material>
    </visual>
    <collision>
      <origin
        xyz="0 0 0"
        rpy="0 0 0" />
      <geometry>
        <mesh
          filename="package://RML-63/meshes/Link_5.STL" />
      </geometry>
    </collision>
  </link>
  <joint
    name="joint_5"
    type="revolute">
    <origin
      xyz="0 0 0"
      rpy="0 0 3.14159265358979" />
    <parent
      link="Link_4" />
    <child
      link="Link_5" />
    <axis
      xyz="0 1 0" />
    <limit
      lower="3.107"
      upper="-3.107"
      effort="100"
      velocity="1" />
  </joint>
  <link
    name="Link_6">
    <inertial>
      <origin
        xyz="-3.30503017647241E-05 -7.04313101298092E-06 -0.0237376311240025"
        rpy="0 0 0" />
      <mass
        value="0.305602476906259" />
      <inertia
        ixx="0.000113828576425154"
        ixy="-3.65313245270359E-08"
        ixz="-1.14220874635304E-07"
        iyy="0.000114694733233837"
        iyz="4.34788884979644E-08"
        izz="0.000126193152406328" />
    </inertial>
    <visual>
      <origin
        xyz="0 0 0"
        rpy="0 0 0" />
      <geometry>
        <mesh
          filename="package://RML-63/meshes/Link_6.STL" />
      </geometry>
      <material
        name="">
        <color
          rgba="0.866666666666667 0.866666666666667 0.890196078431372 1" />
      </material>
    </visual>
    <collision>
      <origin
        xyz="0 0 0"
        rpy="0 0 0" />
      <geometry>
        <mesh
          filename="package://RML-63/meshes/Link_6.STL" />
      </geometry>
    </collision>
  </link>
  <joint
    name="joint_6"
    type="revolute">
    <origin
      xyz="0 0 0.132199355735491"
      rpy="0 0 3.14159265358979" />
    <parent
      link="Link_5" />
    <child
      link="Link_6" />
    <axis
      xyz="0 0 -0.999999999990482" />
    <limit
      lower="3.14"
      upper="-3.14"
      effort="100"
      velocity="1" />
  </joint>
</robot>